<?xml version="1.0" ?>
<!-- =================================================================================== -->
<!-- |    This document was autogenerated by xacro from urdf\doooor_c.xacro.temp       | -->
<!-- |    EDITING THIS FILE BY HAND IS NOT RECOMMENDED                                 | -->
<!-- =================================================================================== -->
<robot xmlns:xacro="http://www.ros.org/wiki/xacro" name="doooor_c">
  <material name="silver">
    <color rgba="0.700 0.700 0.700 1.000"/>
  </material>
  <transmission name="Revolute 5_tran">
    <type>transmission_interface/SimpleTransmission</type>
    <joint name="Revolute 5">
      <hardwareInterface>hardware_interface/EffortJointInterface</hardwareInterface>
    </joint>
    <actuator name="Revolute 5_actr">
      <hardwareInterface>hardware_interface/EffortJointInterface</hardwareInterface>
      <mechanicalReduction>1</mechanicalReduction>
    </actuator>
  </transmission>
  <transmission name="Revolute 6_tran">
    <type>transmission_interface/SimpleTransmission</type>
    <joint name="Revolute 6">
      <hardwareInterface>hardware_interface/EffortJointInterface</hardwareInterface>
    </joint>
    <actuator name="Revolute 6_actr">
      <hardwareInterface>hardware_interface/EffortJointInterface</hardwareInterface>
      <mechanicalReduction>1</mechanicalReduction>
    </actuator>
  </transmission>
  <transmission name="Revolute 7_tran">
    <type>transmission_interface/SimpleTransmission</type>
    <joint name="Revolute 7">
      <hardwareInterface>hardware_interface/EffortJointInterface</hardwareInterface>
    </joint>
    <actuator name="Revolute 7_actr">
      <hardwareInterface>hardware_interface/EffortJointInterface</hardwareInterface>
      <mechanicalReduction>1</mechanicalReduction>
    </actuator>
  </transmission>
  <!-- omitted .gazebo include -->
  <link name="base_link">
    <inertial>
      <origin xyz="7.038694317802445e-05 -1.6801656607224579e-18 0.24500000000000013" rpy="0 0 0"/>
      <mass value="0.16598840834892414"/>
      <inertia ixx="0.003304" iyy="0.003304" izz="1e-06" ixy="-0.0" iyz="-0.0" ixz="-0.0"/>
    </inertial>
    <visual>
      <origin xyz="0 0 0" rpy="0 0 0"/>
      <geometry>
        <mesh filename="package://doooor_c_description/meshes/base_link.stl" scale="0.001 0.001 0.001"/>
      </geometry>
      <material name="silver"/>
    </visual>
    <collision>
      <origin xyz="0 0 0" rpy="0 0 0"/>
      <geometry>
        <mesh filename="package://doooor_c_description/meshes/base_link.stl" scale="0.001 0.001 0.001"/>
      </geometry>
    </collision>
  </link>
  <link name="door_slab_v14_1">
    <inertial>
      <origin xyz="-0.2948919244895614 0.0010000000000000002 0.23501224276984944" rpy="0 0 0"/>
      <mass value="4.35104520375761"/>
      <inertia ixx="0.080071" iyy="0.20627" izz="0.126202" ixy="-0.0" iyz="0.0" ixz="1.6e-05"/>
    </inertial>
    <visual>
      <origin xyz="0.00325 0.001 -0.01" rpy="0 0 0"/>
      <geometry>
        <mesh filename="package://doooor_c_description/meshes/door_slab_v14_1.stl" scale="0.001 0.001 0.001"/>
      </geometry>
      <material name="silver"/>
    </visual>
    <collision>
      <origin xyz="0.00325 0.001 -0.01" rpy="0 0 0"/>
      <geometry>
        <mesh filename="package://doooor_c_description/meshes/door_slab_v14_1.stl" scale="0.001 0.001 0.001"/>
      </geometry>
    </collision>
  </link>
  <link name="door_LatchFixedBaseL_v2_1">
    <inertial>
      <origin xyz="0.49325 0.001 -0.155" rpy="0 0 0"/>
      <mass value="0.0"/>
      <inertia ixx="0.0" iyy="0.0" izz="0.0" ixy="0.0" iyz="0.0" ixz="0.0"/>
    </inertial>
    <visual>
      <origin xyz="0.49325 0.001 -0.155" rpy="0 0 0"/>
      <geometry>
        <mesh filename="package://doooor_c_description/meshes/door_LatchFixedBaseL_v2_1.stl" scale="0.001 0.001 0.001"/>
      </geometry>
      <material name="silver"/>
    </visual>
    <collision>
      <origin xyz="0.49325 0.001 -0.155" rpy="0 0 0"/>
      <geometry>
        <mesh filename="package://doooor_c_description/meshes/door_LatchFixedBaseL_v2_1.stl" scale="0.001 0.001 0.001"/>
      </geometry>
    </collision>
  </link>
  <link name="door_Lockdown_A6_2_v1_1">
    <inertial>
      <origin xyz="0.024451503454100965 -0.010499999999999926 -6.938893903907228e-18" rpy="0 0 0"/>
      <mass value="0.18953373521689193"/>
      <inertia ixx="1.4e-05" iyy="0.000192" izz="0.000192" ixy="-0.0" iyz="0.0" ixz="-0.0"/>
    </inertial>
    <visual>
      <origin xyz="0.53825 0.001 -0.06" rpy="0 0 0"/>
      <geometry>
        <mesh filename="package://doooor_c_description/meshes/door_Lockdown_A6_2_v1_1.stl" scale="0.001 0.001 0.001"/>
      </geometry>
      <material name="silver"/>
    </visual>
    <collision>
      <origin xyz="0.53825 0.001 -0.06" rpy="0 0 0"/>
      <geometry>
        <mesh filename="package://doooor_c_description/meshes/door_Lockdown_A6_2_v1_1.stl" scale="0.001 0.001 0.001"/>
      </geometry>
    </collision>
  </link>
  <link name="door_Lockup_A1_2_v1_1">
    <inertial>
      <origin xyz="0.034908909067310534 -0.010499999999999995 0.0" rpy="0 0 0"/>
      <mass value="0.1895337352168919"/>
      <inertia ixx="1.4e-05" iyy="0.000192" izz="0.000192" ixy="0.0" iyz="-0.0" ixz="-0.0"/>
    </inertial>
    <visual>
      <origin xyz="0.50325 0.001 -0.43" rpy="0 0 0"/>
      <geometry>
        <mesh filename="package://doooor_c_description/meshes/door_Lockup_A1_2_v1_1.stl" scale="0.001 0.001 0.001"/>
      </geometry>
      <material name="silver"/>
    </visual>
    <collision>
      <origin xyz="0.50325 0.001 -0.43" rpy="0 0 0"/>
      <geometry>
        <mesh filename="package://doooor_c_description/meshes/door_Lockup_A1_2_v1_1.stl" scale="0.001 0.001 0.001"/>
      </geometry>
    </collision>
  </link>
  <link name="latch_V4_Row_forupdown_v7_1">
    <inertial>
      <origin xyz="0.06006525734775814 -0.007499999999999951 0.0" rpy="0 0 0"/>
      <mass value="1.1149592858571384"/>
      <inertia ixx="5.8e-05" iyy="0.003566" izz="0.00355" ixy="-0.0" iyz="0.0" ixz="0.0"/>
    </inertial>
    <visual>
      <origin xyz="0.49325 0.021 -0.155" rpy="0 0 0"/>
      <geometry>
        <mesh filename="package://doooor_c_description/meshes/latch_V4_Row_forupdown_v7_1.stl" scale="0.001 0.001 0.001"/>
      </geometry>
      <material name="silver"/>
    </visual>
    <collision>
      <origin xyz="0.49325 0.021 -0.155" rpy="0 0 0"/>
      <geometry>
        <mesh filename="package://doooor_c_description/meshes/latch_V4_Row_forupdown_v7_1.stl" scale="0.001 0.001 0.001"/>
      </geometry>
    </collision>
  </link>
  <link name="latch_V4_down_v7_1">
    <inertial>
      <origin xyz="0.00786947360129453 0.007500000000000022 -0.07487303990560797" rpy="0 0 0"/>
      <mass value="0.9558111430285682"/>
      <inertia ixx="0.002174" iyy="0.002211" izz="7.3e-05" ixy="0.0" iyz="-0.0" ixz="0.000223"/>
    </inertial>
    <visual>
      <origin xyz="0.52325 0.021 -0.155" rpy="0 0 0"/>
      <geometry>
        <mesh filename="package://doooor_c_description/meshes/latch_V4_down_v7_1.stl" scale="0.001 0.001 0.001"/>
      </geometry>
      <material name="silver"/>
    </visual>
    <collision>
      <origin xyz="0.52325 0.021 -0.155" rpy="0 0 0"/>
      <geometry>
        <mesh filename="package://doooor_c_description/meshes/latch_V4_down_v7_1.stl" scale="0.001 0.001 0.001"/>
      </geometry>
    </collision>
  </link>
  <link name="latch_V4_up_v7_1">
    <inertial>
      <origin xyz="-0.003739983671663616 0.007500000000000022 0.16526032904458063" rpy="0 0 0"/>
      <mass value="1.9980111430285712"/>
      <inertia ixx="0.019878" iyy="0.019912" izz="0.000109" ixy="0.0" iyz="-0.0" ixz="0.000345"/>
    </inertial>
    <visual>
      <origin xyz="0.46325 0.021 -0.155" rpy="0 0 0"/>
      <geometry>
        <mesh filename="package://doooor_c_description/meshes/latch_V4_up_v7_1.stl" scale="0.001 0.001 0.001"/>
      </geometry>
      <material name="silver"/>
    </visual>
    <collision>
      <origin xyz="0.46325 0.021 -0.155" rpy="0 0 0"/>
      <geometry>
        <mesh filename="package://doooor_c_description/meshes/latch_V4_up_v7_1.stl" scale="0.001 0.001 0.001"/>
      </geometry>
    </collision>
  </link>
  <link name="latch_V4_handle_v2_1">
    <inertial>
      <origin xyz="-1.4988010832439613e-15 -0.03664411465819092 0.0" rpy="0 0 0"/>
      <mass value="0.9987969219718204"/>
      <inertia ixx="0.000279" iyy="0.000219" izz="0.000279" ixy="0.0" iyz="-0.0" ixz="0.0"/>
    </inertial>
    <visual>
      <origin xyz="0.34325 0.036 -0.155" rpy="0 0 0"/>
      <geometry>
        <mesh filename="package://doooor_c_description/meshes/latch_V4_handle_v2_1.stl" scale="0.001 0.001 0.001"/>
      </geometry>
      <material name="silver"/>
    </visual>
    <collision>
      <origin xyz="0.34325 0.036 -0.155" rpy="0 0 0"/>
      <geometry>
        <mesh filename="package://doooor_c_description/meshes/latch_V4_handle_v2_1.stl" scale="0.001 0.001 0.001"/>
      </geometry>
    </collision>
  </link>
  <link name="door_Lockcover_v1_1">
    <inertial>
      <origin xyz="0.04499999999999227 -0.002999999999999982 -0.010000000000000231" rpy="0 0 0"/>
      <mass value="0.08182061972031829"/>
      <inertia ixx="3e-06" iyy="5.8e-05" izz="5.5e-05" ixy="0.0" iyz="0.0" ixz="0.0"/>
    </inertial>
    <visual>
      <origin xyz="0.51325 0.022 -0.44" rpy="0 0 0"/>
      <geometry>
        <mesh filename="package://doooor_c_description/meshes/door_Lockcover_v1_1.stl" scale="0.001 0.001 0.001"/>
      </geometry>
      <material name="silver"/>
    </visual>
    <collision>
      <origin xyz="0.51325 0.022 -0.44" rpy="0 0 0"/>
      <geometry>
        <mesh filename="package://doooor_c_description/meshes/door_Lockcover_v1_1.stl" scale="0.001 0.001 0.001"/>
      </geometry>
    </collision>
  </link>
  <link name="door_Lockcover_v1__1__1">
    <inertial>
      <origin xyz="0.044999999999991935 -0.0029999999999999437 -0.010000000000000196" rpy="0 0 0"/>
      <mass value="0.08182061972031829"/>
      <inertia ixx="3e-06" iyy="5.8e-05" izz="5.5e-05" ixy="0.0" iyz="0.0" ixz="0.0"/>
    </inertial>
    <visual>
      <origin xyz="0.55825 0.022 -0.07" rpy="0 0 0"/>
      <geometry>
        <mesh filename="package://doooor_c_description/meshes/door_Lockcover_v1__1__1.stl" scale="0.001 0.001 0.001"/>
      </geometry>
      <material name="silver"/>
    </visual>
    <collision>
      <origin xyz="0.55825 0.022 -0.07" rpy="0 0 0"/>
      <geometry>
        <mesh filename="package://doooor_c_description/meshes/door_Lockcover_v1__1__1.stl" scale="0.001 0.001 0.001"/>
      </geometry>
    </collision>
  </link>
  <link name="door_LatchRange_v3__1__1">
    <inertial>
      <origin xyz="0.42999 0.001 -0.20538" rpy="0 0 0"/>
      <mass value="0.0"/>
      <inertia ixx="0.0" iyy="0.0" izz="0.0" ixy="0.0" iyz="0.0" ixz="0.0"/>
    </inertial>
    <visual>
      <origin xyz="0.42999 0.001 -0.20538" rpy="0 0 0"/>
      <geometry>
        <mesh filename="package://doooor_c_description/meshes/door_LatchRange_v3__1__1.stl" scale="0.001 0.001 0.001"/>
      </geometry>
      <material name="silver"/>
    </visual>
    <collision>
      <origin xyz="0.42999 0.001 -0.20538" rpy="0 0 0"/>
      <geometry>
        <mesh filename="package://doooor_c_description/meshes/door_LatchRange_v3__1__1.stl" scale="0.001 0.001 0.001"/>
      </geometry>
    </collision>
  </link>
  <link name="door_LatchRange_v3_1">
    <inertial>
      <origin xyz="0.42999 0.001 -0.10462" rpy="0 0 0"/>
      <mass value="0.0"/>
      <inertia ixx="0.0" iyy="0.0" izz="0.0" ixy="0.0" iyz="0.0" ixz="0.0"/>
    </inertial>
    <visual>
      <origin xyz="0.42999 0.001 -0.10462" rpy="0 0 0"/>
      <geometry>
        <mesh filename="package://doooor_c_description/meshes/door_LatchRange_v3_1.stl" scale="0.001 0.001 0.001"/>
      </geometry>
      <material name="silver"/>
    </visual>
    <collision>
      <origin xyz="0.42999 0.001 -0.10462" rpy="0 0 0"/>
      <geometry>
        <mesh filename="package://doooor_c_description/meshes/door_LatchRange_v3_1.stl" scale="0.001 0.001 0.001"/>
      </geometry>
    </collision>
  </link>
  <joint name="Rigid 1" type="fixed">
    <origin xyz="-0.00325 -0.001 0.01" rpy="0 0 0"/>
    <parent link="base_link"/>
    <child link="door_slab_v14_1"/>
  </joint>
  <joint name="Rigid 2" type="fixed">
    <origin xyz="-0.49 0.0 0.145" rpy="0 0 0"/>
    <parent link="door_slab_v14_1"/>
    <child link="door_LatchFixedBaseL_v2_1"/>
  </joint>
  <joint name="Rigid 3" type="fixed">
    <origin xyz="-0.535 0.0 0.05" rpy="0 0 0"/>
    <parent link="door_slab_v14_1"/>
    <child link="door_Lockdown_A6_2_v1_1"/>
  </joint>
  <joint name="Rigid 4" type="fixed">
    <origin xyz="-0.5 0.0 0.42" rpy="0 0 0"/>
    <parent link="door_slab_v14_1"/>
    <child link="door_Lockup_A1_2_v1_1"/>
  </joint>
  <joint name="Revolute 5" type="continuous">
    <origin xyz="0.0 -0.02 0.0" rpy="0 0 0"/>
    <parent link="door_LatchFixedBaseL_v2_1"/>
    <child link="latch_V4_Row_forupdown_v7_1"/>
    <axis xyz="0.0 1.0 0.0"/>
  </joint>
  <joint name="Revolute 6" type="continuous">
    <origin xyz="-0.03 0.0 0.0" rpy="0 0 0"/>
    <parent link="latch_V4_Row_forupdown_v7_1"/>
    <child link="latch_V4_down_v7_1"/>
    <axis xyz="0.0 1.0 0.0"/>
  </joint>
  <joint name="Revolute 7" type="continuous">
    <origin xyz="0.03 0.0 0.0" rpy="0 0 0"/>
    <parent link="latch_V4_Row_forupdown_v7_1"/>
    <child link="latch_V4_up_v7_1"/>
    <axis xyz="0.0 1.0 0.0"/>
  </joint>
  <joint name="Rigid 8" type="fixed">
    <origin xyz="0.15 -0.015 0.0" rpy="0 0 0"/>
    <parent link="latch_V4_Row_forupdown_v7_1"/>
    <child link="latch_V4_handle_v2_1"/>
  </joint>
  <joint name="Rigid 11" type="fixed">
    <origin xyz="-0.01 -0.021 0.01" rpy="0 0 0"/>
    <parent link="door_Lockup_A1_2_v1_1"/>
    <child link="door_Lockcover_v1_1"/>
  </joint>
  <joint name="Rigid 12" type="fixed">
    <origin xyz="-0.02 -0.021 0.01" rpy="0 0 0"/>
    <parent link="door_Lockdown_A6_2_v1_1"/>
    <child link="door_Lockcover_v1__1__1"/>
  </joint>
  <joint name="Rigid 13" type="fixed">
    <origin xyz="-0.42674 0.0 0.19538" rpy="0 0 0"/>
    <parent link="door_slab_v14_1"/>
    <child link="door_LatchRange_v3__1__1"/>
  </joint>
  <joint name="Rigid 14" type="fixed">
    <origin xyz="-0.42674 0.0 0.09462" rpy="0 0 0"/>
    <parent link="door_slab_v14_1"/>
    <child link="door_LatchRange_v3_1"/>
  </joint>
</robot>
